TALISMAN Log file

2018/06/15-04:40:28 : Log start: EVENT

!!! **************************************************
2018/06/15-04:40:28 : !!! Start test, script file: tst-exc-02.script

// Script:    Tst-main-02.script
// Author:    Arndt von Staa
// Date:      02/dec/2011
// Purpose:   Test basic functionality
// Test throw, correctly catch and rethrow program exceptions
// Due to unhandled exception must cancel and display 4 errors
//
// ==========>>> Must stop with 4 errors and disaster
//
     14 == Declarations
     27 == Test correct program error exception catcher, missing recovery 'c'

>>> 1    Line 28  Tester caught a program exception, context 0 >>
--- EXC: USAGE: Thrown while testing
        Exception thrown in Line: 834  File: ..\sources\tst_exc.cpp

>>> 2    Line 29  Program exception catch command does not recover:  =ExceptionProgram   typeError    tstMessage

######  Unexpected program exception !!!!!

    3    Line 29  vvvvvvvvvvvvvvvvvvvvvvvvvvvvvvvvvvvvvv 
>>> 4    Line 29  Test crash: Program will be cancelled.
 


>>>>>>>>>>>>>>>>>>>>>>>>>>>>>>>>>>>>>>>>>>>>>>>>>>>>>>>>>>>


>>>DISASTER: Test has been cancelled prior to ending !!!

      At Line: 250  In module: ..\sources\gnrctest.cpp

>>>DISASTER: Starting roll back.


>>>DISASTER: Roll back completed. Program will be canceled now !!!


>>>>>>>>>>>>>>>>>>>>>>>>>>>>>>>>>>>>>>>>>>>>>>>>>>>>>>>>>>>


